<sdf version='1.11'>
  <world name='swerve_world'>
    <physics name='1ms' type='bullet'>
      <max_step_size>0.001</max_step_size>
      <real_time_factor>1</real_time_factor>
      <real_time_update_rate>1000</real_time_update_rate>
    </physics>
    <plugin name='gz::sim::systems::Physics' filename='gz-sim-physics-system'/>
    <plugin name='gz::sim::systems::SceneBroadcaster' filename='gz-sim-scene-broadcaster-system'/>
    <plugin name='gz::sim::systems::UserCommands' filename='gz-sim-user-commands-system'/>
    <light name='sun' type='directional'>
      <cast_shadows>true</cast_shadows>
      <pose>0 0 10 0 0 0</pose>
      <diffuse>0.800000012 0.800000012 0.800000012 1</diffuse>
      <specular>0.200000003 0.200000003 0.200000003 1</specular>
      <direction>-0.5 0.10000000000000001 -0.90000000000000002</direction>
      <attenuation>
        <range>10</range>
      </attenuation>
      <spot>
        <inner_angle>0</inner_angle>
        <outer_angle>0</outer_angle>
        <falloff>0</falloff>
      </spot>
    </light>
    <model name='ground_plane'>
      <static>true</static>
      <link name='link'>
        <collision name='collision'>
          <geometry>
            <plane>
              <normal>0 0 1</normal>
              <size>1 1</size>
            </plane>
          </geometry>
          <surface>
            <friction>
              <ode>
                <mu>1</mu>
                <mu2>1</mu2>
              </ode>
            </friction>
          </surface>
        </collision>
      </link>
    </model>
    <model name='three_wheel_swerve'>
      <pose>0 0 0.13 0 0 0</pose>
      <link name='base_link'>
        <inertial>
          <pose>0 0 0 0 0 0</pose>
          <mass>15</mass>
          <inertia>
            <ixx>0.33750000000000002</ixx>
            <ixy>0</ixy>
            <ixz>0</ixz>
            <iyy>0.33750000000000002</iyy>
            <iyz>0</iyz>
            <izz>0.67500000000000004</izz>
          </inertia>
        </inertial>
        <visual name='chassis_visual'>
          <geometry>
            <cylinder>
              <radius>0.29999999999999999</radius>
              <length>0.050000000000000003</length>
            </cylinder>
          </geometry>
          <material>
            <ambient>0.100000001 0.100000001 0.100000001 1</ambient>
            <diffuse>0.100000001 0.100000001 0.100000001 1</diffuse>
          </material>
        </visual>
        <collision name='chassis_collision'>
          <geometry>
            <cylinder>
              <radius>0.29999999999999999</radius>
              <length>0.050000000000000003</length>
            </cylinder>
          </geometry>
        </collision>
      </link>
      <link name='steer_link_1'>
        <pose>0.29999999999999999 0 -0.025000000000000001 0 0 0</pose>
        <inertial>
          <mass>1.5</mass>
          <inertia>
            <ixx>0.00215</ixx>
            <ixy>0</ixy>
            <ixz>0</ixz>
            <iyy>0.00215</iyy>
            <iyz>0</iyz>
            <izz>0.0027000000000000001</izz>
          </inertia>
        </inertial>
        <visual name='steer_1_visual'>
          <geometry>
            <cylinder>
              <radius>0.059999999999999998</radius>
              <length>0.080000000000000002</length>
            </cylinder>
          </geometry>
          <material>
            <ambient>0.800000012 0.100000001 0.100000001 1</ambient>
            <diffuse>0.800000012 0.100000001 0.100000001 1</diffuse>
          </material>
        </visual>
        <collision name='steer_1_collision'>
          <geometry>
            <cylinder>
              <radius>0.059999999999999998</radius>
              <length>0.080000000000000002</length>
            </cylinder>
          </geometry>
        </collision>
      </link>
      <link name='wheel_link_1'>
        <pose>0.29999999999999999 0 -0.065000000000000002 1.5708 0 0</pose>
        <inertial>
          <mass>0.80000000000000004</mass>
          <inertia>
            <ixx>0.00059999999999999995</ixx>
            <ixy>0</ixy>
            <ixz>0</ixz>
            <iyy>0.00059999999999999995</iyy>
            <iyz>0</iyz>
            <izz>0.001</izz>
          </inertia>
        </inertial>
        <visual name='wheel_1_visual'>
          <geometry>
            <cylinder>
              <radius>0.050000000000000003</radius>
              <length>0.040000000000000001</length>
            </cylinder>
          </geometry>
          <material>
            <ambient>0.300000012 0.300000012 0.300000012 1</ambient>
            <diffuse>0.300000012 0.300000012 0.300000012 1</diffuse>
          </material>
        </visual>
        <collision name='wheel_1_collision'>
          <geometry>
            <cylinder>
              <radius>0.050000000000000003</radius>
              <length>0.040000000000000001</length>
            </cylinder>
          </geometry>
          <surface>
            <friction>
              <ode>
              <mu>1.0</mu>
              <mu2>1.0</mu2>
              </ode>
            </friction>
          </surface>
        </collision>
      </link>
      <joint name='steer_joint_1' type='revolute'>
        <parent>base_link</parent>
        <child>steer_link_1</child>
        <axis>
          <xyz expressed_in='__model__'>0 0 1</xyz>
          <limit>
            <lower>-3.1415899999999999</lower>
            <upper>3.1415899999999999</upper>
            <effort>10</effort>
            <velocity>5</velocity>
          </limit>
          <dynamics>
            <damping>0.10000000000000001</damping>
            <friction>0.01</friction>
            <spring_reference>0</spring_reference>
            <spring_stiffness>0</spring_stiffness>
          </dynamics>
        </axis>
      </joint>
      <joint name='wheel_joint_1' type='revolute'>
        <parent>steer_link_1</parent>
        <child>wheel_link_1</child>
        <axis>
          <xyz expressed_in='__model__'>0 1 0</xyz>
          <limit>
            <lower>-1e16</lower>
            <upper>1e16</upper>
            <effort>10</effort>
            <velocity>20</velocity>
          </limit>
          <dynamics>
            <damping>0.05</damping>
            <friction>0.01</friction>
          </dynamics>
        </axis>
      </joint>
      <link name='steer_link_2'>
        <pose>-0.15 0.2598 -0.025 0 0 0</pose>
        <inertial>
          <mass>1.5</mass>
          <inertia>
            <ixx>0.00215</ixx>
            <ixy>0</ixy>
            <ixz>0</ixz>
            <iyy>0.00215</iyy>
            <iyz>0</iyz>
            <izz>0.0027</izz>
          </inertia>
        </inertial>
        <visual name='steer_2_visual'>
          <geometry>
            <cylinder><radius>0.06</radius><length>0.08</length></cylinder>
          </geometry>
          <material>
            <ambient>0.8 0.1 0.1 1.0</ambient>
            <diffuse>0.8 0.1 0.1 1.0</diffuse>
          </material>
        </visual>
        <collision name='steer_2_collision'>
          <geometry>
            <cylinder><radius>0.06</radius><length>0.08</length></cylinder>
          </geometry>
        </collision>
      </link>
      <link name='wheel_link_2'>
        <pose>-0.15 0.2598 -0.065 1.5708 0 0</pose>
        <inertial>
          <mass>0.8</mass>
          <inertia>
            <ixx>0.0006</ixx>
            <ixy>0</ixy>
            <ixz>0</ixz>
            <iyy>0.0006</iyy>
            <iyz>0</iyz>
            <izz>0.001</izz>
          </inertia>
        </inertial>
        <visual name='wheel_2_visual'>
          <geometry>
            <cylinder><radius>0.05</radius><length>0.04</length></cylinder>
          </geometry>
          <material>
            <ambient>0.3 0.3 0.3 1.0</ambient>
            <diffuse>0.3 0.3 0.3 1.0</diffuse>
          </material>
        </visual>
        <collision name='wheel_2_collision'>
          <geometry>
            <cylinder><radius>0.05</radius><length>0.04</length></cylinder>
          </geometry>
          <surface>
            <friction>
              <ode>
                <mu>1.0</mu>
                <mu2>1.0</mu2>
              </ode>
            </friction>
          </surface>
        </collision>
      </link>
      <joint name='steer_joint_2' type='revolute'>
        <parent>base_link</parent>
        <child>steer_link_2</child>
        <axis>
          <xyz expressed_in='__model__'>0 0 1</xyz>
          <limit>
            <lower>-3.14159</lower>
            <upper>3.14159</upper>
            <effort>10</effort>
            <velocity>5</velocity>
          </limit>
          <dynamics>
            <damping>0.1</damping>
            <friction>0.01</friction>
          </dynamics>
        </axis>
      </joint>
      <joint name='wheel_joint_2' type='revolute'>
        <parent>steer_link_2</parent>
        <child>wheel_link_2</child>
        <axis>
          <xyz expressed_in='__model__'>0 1 0</xyz>
          <limit>
            <lower>-1e16</lower>
            <upper>1e16</upper>
            <effort>10</effort>
            <velocity>20</velocity>
          </limit>
          <dynamics>
            <damping>0.05</damping>
            <friction>0.01</friction>
          </dynamics>
        </axis>
      </joint>
      <link name='steer_link_3'>
        <pose>-0.15 -0.2598 -0.025 0 0 0</pose>
        <inertial>
          <mass>1.5</mass>
          <inertia>
            <ixx>0.00215</ixx>
            <ixy>0</ixy>
            <ixz>0</ixz>
            <iyy>0.00215</iyy>
            <iyz>0</iyz>
            <izz>0.0027</izz>
          </inertia>
        </inertial>
        <visual name='steer_3_visual'>
          <geometry>
            <cylinder><radius>0.06</radius><length>0.08</length></cylinder>
          </geometry>
          <material>
            <ambient>0.8 0.1 0.1 1.0</ambient>
            <diffuse>0.8 0.1 0.1 1.0</diffuse>
          </material>
        </visual>
        <collision name='steer_3_collision'>
          <geometry>
            <cylinder><radius>0.06</radius><length>0.08</length></cylinder>
          </geometry>
        </collision>
      </link>
      <link name='wheel_link_3'>
        <pose>-0.15 -0.2598 -0.065 1.5708 0 0</pose>
        <inertial>
          <mass>0.8</mass>
          <inertia>
            <ixx>0.0006</ixx>
            <ixy>0</ixy>
            <ixz>0</ixz>
            <iyy>0.0006</iyy>
            <iyz>0</iyz>
            <izz>0.001</izz>
          </inertia>
        </inertial>
        <visual name='wheel_3_visual'>
          <geometry>
            <cylinder><radius>0.05</radius><length>0.04</length></cylinder>
          </geometry>
          <material>
            <ambient>0.3 0.3 0.3 1.0</ambient>
            <diffuse>0.3 0.3 0.3 1.0</diffuse>
          </material>
        </visual>
        <collision name='wheel_3_collision'>
          <geometry>
            <cylinder><radius>0.05</radius><length>0.04</length></cylinder>
          </geometry>
          <surface>
            <friction>
              <ode>
                <mu>1.0</mu>
                <mu2>1.0</mu2>
              </ode>
            </friction>
          </surface>
        </collision>
      </link>
      <joint name='steer_joint_3' type='revolute'>
        <parent>base_link</parent>
        <child>steer_link_3</child>
        <axis>
          <xyz expressed_in='__model__'>0 0 1</xyz>
          <limit>
            <lower>-3.14159</lower>
            <upper>3.14159</upper>
            <effort>10</effort>
            <velocity>5</velocity>
          </limit>
          <dynamics>
            <damping>0.1</damping>
            <friction>0.01</friction>
          </dynamics>
        </axis>
      </joint>
      <joint name='wheel_joint_3' type='revolute'>
        <parent>steer_link_3</parent>
        <child>wheel_link_3</child>
        <axis>
          <xyz expressed_in='__model__'>0 1 0</xyz>
          <limit>
            <lower>-10000000000000000</lower>
            <upper>10000000000000000</upper>
            <effort>10</effort>
            <velocity>20</velocity>
          </limit>
          <dynamics>
            <damping>0.050000000000000003</damping>
            <friction>0.01</friction>
            <spring_reference>0</spring_reference>
            <spring_stiffness>0</spring_stiffness>
          </dynamics>
        </axis>
      </joint>
      <plugin filename="gz-sim-joint-state-publisher-system"
        name="gz::sim::systems::JointStatePublisher">
      </plugin>
      <plugin name='gz::sim::systems::JointPositionController' filename='gz-sim-joint-position-controller-system'>
        <joint_name>steer_joint_1</joint_name>
        <topic>/model/three_wheel_swerve/joint/steer_joint_1/cmd_pos</topic>
        <p_gain>100.0</p_gain>
        <i_gain>0.0</i_gain>
        <d_gain>1.0</d_gain>
      </plugin>
      <plugin name='gz::sim::systems::JointController' filename='gz-sim-joint-controller-system'>
        <joint_name>wheel_joint_1</joint_name>
        <topic>/model/three_wheel_swerve/joint/wheel_joint_1/cmd_vel</topic>
        <p_gain>200.0</p_gain>
        <i_gain>0.1</i_gain>
        <d_gain>1.0</d_gain>
      </plugin>

      <plugin name='gz::sim::systems::JointPositionController' filename='gz-sim-joint-position-controller-system'>
        <joint_name>steer_joint_2</joint_name>
        <topic>/model/three_wheel_swerve/joint/steer_joint_2/cmd_pos</topic>
        <p_gain>100.0</p_gain>
        <i_gain>0.0</i_gain>
        <d_gain>1.0</d_gain>
      </plugin>
      <plugin name='gz::sim::systems::JointController' filename='gz-sim-joint-controller-system'>
        <joint_name>wheel_joint_2</joint_name>
        <topic>/model/three_wheel_swerve/joint/wheel_joint_2/cmd_vel</topic>
        <p_gain>200.0</p_gain>
        <i_gain>0.1</i_gain>
        <d_gain>1.0</d_gain>
      </plugin>

      <plugin name='gz::sim::systems::JointPositionController' filename='gz-sim-joint-position-controller-system'>
        <joint_name>steer_joint_3</joint_name>
        <topic>/model/three_wheel_swerve/joint/steer_joint_3/cmd_pos</topic>
        <p_gain>100.0</p_gain>
        <i_gain>0.0</i_gain>
        <d_gain>1.0</d_gain>
      </plugin>
      <plugin name='gz::sim::systems::JointController' filename='gz-sim-joint-controller-system'>
        <joint_name>wheel_joint_3</joint_name>
        <topic>/model/three_wheel_swerve/joint/wheel_joint_3/cmd_vel</topic>
        <p_gain>200.0</p_gain>
        <i_gain>0.1</i_gain>
        <d_gain>1.0</d_gain>
      </plugin>
    </model>
    <gravity>0 0 -9.8000000000000007</gravity>
    <magnetic_field>5.5644999999999998e-06 2.2875799999999999e-05 -4.2388400000000002e-05</magnetic_field>
    <atmosphere type='adiabatic'/>
    <scene>
      <ambient>0.400000006 0.400000006 0.400000006 1</ambient>
      <background>0.699999988 0.699999988 0.699999988 1</background>
      <shadows>true</shadows>
    </scene>
  </world>
</sdf>
